<?xml version="1.0"?>

<robot name="robot" xmlns:xacro="http://www.ros.org/wiki/xacro">

    <xacro:include filename="$(find isa_afa_3)/src/description/robot.gazebo" />

    <!-- Parameters -->
    <xacro:property name="chassis_mass" value="10" />

    <!-- LINKS -->

    <!-- Link - chassis -->
    <link name="base_link">
        <inertial>
            <mass value="${chassis_mass}" />
            <origin xyz="0 0 0.3" rpy="0 0 0" />
            <inertia ixx="1.5417" ixy="0" ixz="0" iyy="3.467" iyz="0" izz="4.742" />
        </inertial>

        <collision>
            <origin xyz="0 0 0" rpy="0 0 0"/>
            <geometry>
                <mesh filename="package://isa_afa_3/meshes/chassis.stl"/>
            </geometry>
        </collision>

        <visual>
            <origin xyz="0 0 0" rpy="0 0 0"/>
            <geometry>
                <mesh filename="package://isa_afa_3/meshes/chassis.stl"/>
            </geometry>
            <material name="DarkBlue">
                <color rgba="0.2 0.2 0.4 1" />
            </material>
        </visual>
    </link>

    <!-- Robot Footprint -->
    <link name='base_footprint'>
        <inertial>
            <mass value="${chassis_mass}" />
            <origin xyz="0 0 0.3" rpy="0 0 0" />
            <inertia ixx="1.5417" ixy="0" ixz="0" iyy="3.467" iyz="0" izz="4.742" />
        </inertial>
    </link>

    <!-- Link - rear left wheel -->
    <link name="rear_left_wheel_link">
        <inertial>
            <mass value="1" />
            <origin xyz="0 0 0" rpy="0 0 0" />
            <inertia ixx="0.002526666666667" ixy="0" ixz="0" iyy="0.002526666666667" iyz="0" izz="0.005"/>
        </inertial>

        <collision>
            <origin xyz="0 0 0" rpy="0 0 0"/>
            <geometry>
                <mesh filename="package://isa_afa_3/meshes/wheel_left.stl" />
            </geometry>
        </collision>

        <visual>
            <origin xyz="0 0 0" rpy="0 0 0"/>
            <geometry>
                <mesh filename="package://isa_afa_3/meshes/wheel_left.stl" />
            </geometry>
            <material name="Black">
                <color rgba="0.1 0.1 0.1 1" />
            </material>
        </visual>
    </link>

    <!-- Link - rear right wheel -->
    <link name="rear_right_wheel_link">
        <inertial>
            <mass value="1" />
            <origin xyz="0 0 0" rpy="0 0 0" />
            <inertia ixx="0.002526666666667" ixy="0" ixz="0" iyy="0.002526666666667" iyz="0" izz="0.005"/>
        </inertial>

        <collision>
            <origin xyz="0 0 0" rpy="0 0 0"/>
            <geometry>
                <mesh filename="package://isa_afa_3/meshes/wheel_right.stl" />
            </geometry>
        </collision>

        <visual>
            <origin xyz="0 0 0" rpy="0 0 0"/>
            <geometry>
                <mesh filename="package://isa_afa_3/meshes/wheel_right.stl" />
            </geometry>
            <material name="Black">
                <color rgba="0.1 0.1 0.1 1" />
            </material>
        </visual>
    </link>

    <!-- Link - front left wheel -->
    <link name="front_left_wheel_link">
        <inertial>
            <mass value="1" />
            <origin xyz="0 0 0" rpy="0 0 0" />
            <inertia ixx="0.002526666666667" ixy="0" ixz="0" iyy="0.002526666666667" iyz="0" izz="0.005"/>
        </inertial>

        <collision>
            <origin xyz="0 0 0" rpy="0 0 0"/>
            <geometry>
                <mesh filename="package://isa_afa_3/meshes/wheel_left.stl" />
            </geometry>
        </collision>

        <visual>
            <origin xyz="0 0 0" rpy="0 0 0"/>
            <geometry>
                <mesh filename="package://isa_afa_3/meshes/wheel_left.stl" />
            </geometry>
            <material name="Black">
                <color rgba="0.1 0.1 0.1 1" />
            </material>
        </visual>
    </link>

    <!-- Link - front right wheel -->
    <link name="front_right_wheel_link">
        <inertial>
            <mass value="1" />
            <origin xyz="0 0 0" rpy="0 0 0" />
            <inertia ixx="0.002526666666667" ixy="0" ixz="0" iyy="0.002526666666667" iyz="0" izz="0.005"/>
        </inertial>

        <collision>
            <origin xyz="0 0 0" rpy="0 0 0"/>
            <geometry>
                <mesh filename="package://isa_afa_3/meshes/wheel_right.stl" />
            </geometry>
        </collision>

        <visual>
            <origin xyz="0 0 0" rpy="0 0 0"/>
            <geometry>
                <mesh filename="package://isa_afa_3/meshes/wheel_right.stl" />
            </geometry>
            <material name="Black">
                <color rgba="0.1 0.1 0.1 1" />
            </material>
        </visual>
    </link>

    <!-- Link - front axle -->
    <link name="front_axle_link">
        <inertial>
            <mass value="1" />
            <origin xyz="0 0 0" rpy="0 0 0" />
            <inertia ixx="0.002526666666667" ixy="0" ixz="0" iyy="0.002526666666667" iyz="0" izz="0.005"/>
        </inertial>

        <collision>
            <origin rpy="${pi/2} 0 0" xyz="0 0 0"/>
            <geometry>
                <cylinder length="1.4" radius="0.1"/>
            </geometry>
        </collision>

        <visual>
            <origin rpy="${pi/2} 0 0" xyz="0 0 0"/>
            <geometry>
                <cylinder length="1.4" radius="0.1"/>
            </geometry>
            <material name="Black">
                <color rgba="0.1 0.1 0.1 1" />
            </material>
        </visual>
    </link>

    <!-- Link - rear axle -->
    <link name="rear_axle_link">
        <inertial>
            <mass value="1" />
            <origin xyz="0 0 0" rpy="0 0 0" />
            <inertia ixx="0.002526666666667" ixy="0" ixz="0" iyy="0.002526666666667" iyz="0" izz="0.005"/>
        </inertial>

        <collision>
            <origin rpy="${pi/2} 0 0" xyz="0 0 0"/>
            <geometry>
                <cylinder length="1.4" radius="0.1"/>
            </geometry>
        </collision>

        <visual>
            <origin rpy="${pi/2} 0 0" xyz="0 0 0"/>
            <geometry>
                <cylinder length="1.4" radius="0.1"/>
            </geometry>
            <material name="Black">
                <color rgba="0.1 0.1 0.1 1" />
            </material>
        </visual>
    </link>

    <!-- Link - left hinge -->
    <link name="left_hinge_link">
        <inertial>
            <mass value="0.001"/>
            <inertia ixx="0.001" ixy = "0" ixz = "0" iyy="0.001" iyz = "0" izz="0.001"/>
        </inertial>
    </link>

    <!-- Link - right hinge -->
    <link name="right_hinge_link">
        <inertial>
            <mass value="0.001"/>
            <inertia ixx="0.001" ixy = "0" ixz = "0" iyy="0.001" iyz = "0" izz="0.001"/>
        </inertial>
    </link>

    <!-- JOINTS -->

    <!-- Joint - chassis / front axle -->
    <joint name="chassis_front_axle_joint" type="fixed">
        <origin rpy="0 0 0" xyz="0 0 0" />
        <child link="front_axle_link" />
        <parent link="base_link" />
        <joint_properties damping="1.0" friction="1.0" />
    </joint>

    <joint name='base_joint' type='fixed'>
        <origin rpy="0 0 0" xyz="0 0 0" />
        <child link="base_footprint" />
        <parent link="base_link" />
    </joint>

    <!-- Joint - chassis / rear axle -->
    <joint name="chassis_rear_axle_joint" type="fixed">
        <origin rpy="0 0 0" xyz="-2.6 0 0" />
        <child link="rear_axle_link" />
        <parent link="base_link" />
        <joint_properties damping="1.0" friction="1.0" />
    </joint>

    <!-- Joint - front axle / left hinge -->
    <joint name="steering_left_hinge_joint" type="revolute">
        <child link="left_hinge_link" />
        <parent link="front_axle_link" />
        <origin xyz="0 0.7 0" rpy="0 0 0" />
        <axis xyz="0 0 1" />
        <limit lower="-0.7" upper="0.7" effort="10" velocity="100" />
    </joint>

    <!-- Joint - front axle / right hinge -->
    <joint name="steering_right_hinge_joint" type="revolute">
        <child link="right_hinge_link" />
        <parent link="front_axle_link" />
        <origin xyz="0 -0.7 0" rpy="0 0 0" />
        <axis xyz="0 0 1" />
        <limit lower="-0.7" upper="0.7" effort="10" velocity="100" />
    </joint>

    <!-- Joint - left hinge / front left wheel -->
    <joint name="left_hinge_wheel_joint" type="continuous">
        <child link="front_left_wheel_link" />
        <parent link="left_hinge_link" />
        <origin xyz="0 0 0" rpy="0 0 0" />
        <axis xyz="0 1 0" />
    </joint>

    <!-- Joint - right hinge / front right wheel -->
    <joint name="right_hinge_wheel_joint" type="continuous">
        <child link="front_right_wheel_link" />
        <parent link="right_hinge_link" />
        <origin xyz="0 0 0" rpy="0 0 0" />
        <axis xyz="0 1 0" />
    </joint>

    <!-- Joint - rear axle / rear left wheel -->
    <joint name="rear_axle_left_wheel_joint" type="continuous">
        <child link="rear_left_wheel_link" />
        <parent link="rear_axle_link" />
        <origin xyz="0 0.7 0" rpy="0 0 0" />
        <axis xyz="0 1 0" />
    </joint>

    <!-- Joint - rear axle / rear right wheel -->
    <joint name="rear_axle_right_wheel_joint" type="continuous">
        <child link="rear_right_wheel_link" />
        <parent link="rear_axle_link" />
        <origin xyz="0 -0.7 0" rpy="0 0 0" />
        <axis xyz="0 1 0" />
    </joint>

    <!-- Laser scan -->
    <joint name="lidar_joint" type="fixed">
        <origin rpy="0 0 0" xyz="-1.3 0 1.6" />
        <child link="lidar_link" />
        <parent link="base_link" />
        <joint_properties damping="1.0" friction="1.0" />
    </joint>
    <link name="lidar_link">
        <inertial>
            <origin xyz="0 0 0" rpy="0 0 0" />
            <mass value="0.5" />
            <inertia ixx="0.000252666666667" ixy="0" ixz="0" iyy="0.000252666666667" iyz="0" izz="0.0005"/>
        </inertial>
        <visual>
            <origin xyz="0 0 0" rpy="0 0 0" />
            <geometry>
                <cylinder radius="0.15" length="0.40"/>
            </geometry>
            <material name="Red">
                <color rgba="0.7 0.1 0.1 1" />
            </material>
        </visual>
        <collision>
            <origin xyz="0 0 0" rpy="0 0 0"/>
            <geometry>
                <cylinder radius="0.15" length="0.40"/>
            </geometry>
        </collision>
    </link>

</robot>
