<?xml version="1.0"?>

<robot name="robot" xmlns:xacro="http://www.ros.org/wiki/xacro">

    <xacro:include filename="$(find ackermann_robot_description)/urdf/robot.gazebo" />

    <!-- Parameters -->
    <xacro:property name="chassis_mass" value="10" />

    <!-- LINKS -->

    <!-- Link - chassis -->
    <link name="link_chassis">
        <inertial>
            <mass value="${chassis_mass}" />
            <origin xyz="0 0 0.3" rpy="0 0 0" />
            <inertia ixx="1.5417" ixy="0" ixz="0" iyy="3.467" iyz="0" izz="4.742" />
        </inertial>

        <collision>
            <geometry>
                <mesh filename="package://ackermann_robot_description/meshes/chassis.stl" />
            </geometry>
        </collision>

        <visual>
            <geometry>
                <mesh filename="package://ackermann_robot_description/meshes/chassis.stl" />
            </geometry>
            <material name="DarkBlue">
                <color rgba="0.2 0.2 0.4 1" />
            </material>
        </visual>
    </link>

    <!-- Link - rear left wheel -->
    <link name="link_rear_left_wheel">
        <inertial>
            <mass value="1" />
            <origin xyz="0 0 0" rpy="0 0 0" />
            <inertia ixx="0.002526666666667" ixy="0" ixz="0" iyy="0.002526666666667" iyz="0" izz="0.005"/>
        </inertial>

        <!-- Tires -->
        <collision>
            <origin rpy="${pi/2} 0 0" xyz="0 0.18 0" />
            <geometry>
                <cylinder length="0.12" radius="0.4"/>
            </geometry>
        </collision>
        <visual>
            <origin rpy="${pi/2} 0 0" xyz="0 0.18 0" />
            <geometry>
                <mesh filename="package://ackermann_robot_description/meshes/wheel.stl" />
            </geometry>
            <material name="Black">
                <color rgba="0.1 0.1 0.1 1" />
            </material>
        </visual>

        <!-- Axle -->
        <collision>
            <origin rpy="${pi/2} 0 0" xyz="0 0.06 0" />
            <geometry>
                <cylinder length="0.12" radius="0.08"/>
            </geometry>
        </collision>
        <visual>
            <origin rpy="${pi/2} 0 0" xyz="0 0.06 0" />
            <geometry>
                <cylinder length="0.12" radius="0.08"/>
            </geometry>
            <material name="Grey">
                <color rgba="0.6 0.6 0.6 1" />
            </material>
        </visual>

        <!-- Hubcap -->
        <visual>
            <origin rpy="${pi/2} 0 0" xyz="0 0.18 0" />
            <geometry>
                <box size="0.02 0.5 0.02" />
            </geometry>
            <material name="Grey">
                <color rgba="0.6 0.6 0.6 1" />
            </material>
        </visual>
    </link>

    <!-- Link - rear right wheel -->
    <link name="link_rear_right_wheel">
        <inertial>
            <mass value="1" />
            <origin xyz="0 0 0" rpy="0 0 0" />
            <inertia ixx="0.002526666666667" ixy="0" ixz="0" iyy="0.002526666666667" iyz="0" izz="0.005"/>
        </inertial>

        <!-- Tires -->
        <collision>
            <origin rpy="${pi/2} 0 0" xyz="0 -0.18 0" />
            <geometry>
                <cylinder length="0.12" radius="0.4"/>
            </geometry>
        </collision>
        <visual>
            <origin rpy="${pi/2} 0 0" xyz="0 -0.18 0" />
            <geometry>
                <mesh filename="package://ackermann_robot_description/meshes/wheel.stl" />
            </geometry>
            <material name="Black">
                <color rgba="0.1 0.1 0.1 1" />
            </material>
        </visual>

        <!-- Axle -->
        <collision>
            <origin rpy="${pi/2} 0 0" xyz="0 -0.06 0" />
            <geometry>
                <cylinder length="0.12" radius="0.08"/>
            </geometry>
        </collision>
        <visual>
            <origin rpy="${pi/2} 0 0" xyz="0 -0.06 0" />
            <geometry>
                <cylinder length="0.12" radius="0.08"/>
            </geometry>
            <material name="Grey">
                <color rgba="0.6 0.6 0.6 1" />
            </material>
        </visual>

        <!-- Hubcap -->
        <visual>
            <origin rpy="${pi/2} 0 0" xyz="0 -0.18 0" />
            <geometry>
                <box size="0.02 0.5 0.02" />
            </geometry>
            <material name="Grey">
                <color rgba="0.6 0.6 0.6 1" />
            </material>
        </visual>
    </link>

    <!-- Link - front left wheel -->
    <link name="link_front_left_wheel">
        <inertial>
            <mass value="1" />
            <origin xyz="0 0 0" rpy="0 0 0" />
            <inertia ixx="0.002526666666667" ixy="0" ixz="0" iyy="0.002526666666667" iyz="0" izz="0.005"/>
        </inertial>

        <!-- Tires -->
        <collision>
            <origin rpy="${pi/2} 0 0" xyz="0 0.18 0" />
            <geometry>
                <cylinder length="0.12" radius="0.4"/>
            </geometry>
        </collision>
        <visual>
            <origin rpy="${pi/2} 0 0" xyz="0 0.18 0" />
            <geometry>
                <mesh filename="package://ackermann_robot_description/meshes/wheel.stl" />
            </geometry>
            <material name="Black">
                <color rgba="0.1 0.1 0.1 1" />
            </material>
        </visual>

        <!-- Axle -->
        <collision>
            <origin rpy="${pi/2} 0 0" xyz="0 0.06 0" />
            <geometry>
                <cylinder length="0.12" radius="0.08"/>
            </geometry>
        </collision>
        <visual>
            <origin rpy="${pi/2} 0 0" xyz="0 0.06 0" />
            <geometry>
                <cylinder length="0.12" radius="0.08"/>
            </geometry>
            <material name="Grey">
                <color rgba="0.6 0.6 0.6 1" />
            </material>
        </visual>

        <!-- Hubcap -->
        <visual>
            <origin rpy="${pi/2} 0 0" xyz="0 0.18 0" />
            <geometry>
                <box size="0.02 0.5 0.02" />
            </geometry>
            <material name="Grey">
                <color rgba="0.6 0.6 0.6 1" />
            </material>
        </visual>
    </link>

    <!-- Link - front right wheel -->
    <link name="link_front_right_wheel">
        <inertial>
            <mass value="1" />
            <origin xyz="0 0 0" rpy="0 0 0" />
            <inertia ixx="0.002526666666667" ixy="0" ixz="0" iyy="0.002526666666667" iyz="0" izz="0.005"/>
        </inertial>

        <!-- Tires -->
        <collision>
            <origin rpy="${pi/2} 0 0" xyz="0 -0.18 0" />
            <geometry>
                <cylinder length="0.12" radius="0.4"/>
            </geometry>
        </collision>
        <visual>
            <origin rpy="${pi/2} 0 0" xyz="0 -0.18 0" />
            <geometry>
                <mesh filename="package://ackermann_robot_description/meshes/wheel.stl" />
            </geometry>
            <material name="Black">
                <color rgba="0.1 0.1 0.1 1" />
            </material>
        </visual>

        <!-- Axle -->
        <collision>
            <origin rpy="${pi/2} 0 0" xyz="0 -0.06 0" />
            <geometry>
                <cylinder length="0.12" radius="0.08"/>
            </geometry>
        </collision>
        <visual>
            <origin rpy="${pi/2} 0 0" xyz="0 -0.06 0" />
            <geometry>
                <cylinder length="0.12" radius="0.08"/>
            </geometry>
            <material name="Grey">
                <color rgba="0.6 0.6 0.6 1" />
            </material>
        </visual>

        <!-- Hubcap -->
        <visual>
            <origin rpy="${pi/2} 0 0" xyz="0 -0.18 0" />
            <geometry>
                <box size="0.02 0.5 0.02" />
            </geometry>
            <material name="Grey">
                <color rgba="0.6 0.6 0.6 1" />
            </material>
        </visual>
    </link>

    <!-- Link - left hinge -->
    <link name="link_left_hinge">
        <inertial>
            <mass value="0.001"/>
            <inertia ixx="0.001" ixy = "0" ixz = "0" iyy="0.001" iyz = "0" izz="0.001"/>
        </inertial>
    </link>

    <!-- Link - right hinge -->
    <link name="link_right_hinge">
        <inertial>
            <mass value="0.001"/>
            <inertia ixx="0.001" ixy = "0" ixz = "0" iyy="0.001" iyz = "0" izz="0.001"/>
        </inertial>
    </link>

    <!-- JOINTS -->

    <!-- Joint - chassis / rear left wheel -->
    <joint name="joint_chassis_rear_left_wheel" type="continuous">
        <origin rpy="0 0 0" xyz="-0.5 0.65 0" />
        <child link="link_rear_left_wheel" />
        <parent link="link_chassis" />
        <axis rpy="0 0 0" xyz="0 1 0" />
        <limit effort="10000" velocity="1000" />
        <joint_properties damping="1.0" friction="1.0" />
    </joint>

    <!-- Joint - chassis / rear right wheel -->
    <joint name="joint_chassis_rear_right_wheel" type="continuous">
        <origin rpy="0 0 0" xyz="-0.5 -0.65 0" />
        <child link="link_rear_right_wheel" />
        <parent link="link_chassis" />
        <axis rpy="0 0 0" xyz="0 1 0" />
        <limit effort="10000" velocity="1000" />
        <joint_properties damping="1.0" friction="1.0" />
    </joint>

    <!-- Joint - chassis / left hinge -->
    <joint name="joint_steering_left_hinge" type="revolute">
        <child link="link_left_hinge" />
        <parent link="link_chassis" />
        <origin xyz="0.5 0.65 0" rpy="0 0 0" />
        <axis xyz="0 0 1" />
        <limit lower="-0.7" upper="0.7" effort="10" velocity="100" />
    </joint>

    <!-- Joint - chassis / right hinge -->
    <joint name="joint_steering_right_hinge" type="revolute">
        <child link="link_right_hinge" />
        <parent link="link_chassis" />
        <origin xyz="0.5 -0.65 0" rpy="0 0 0" />
        <axis xyz="0 0 1" />
        <limit lower="-0.7" upper="0.7" effort="10" velocity="100" />
    </joint>

    <!-- Joint - left hinge / front left wheel -->
    <joint name="joint_left_hinge_wheel" type="continuous">
        <child link="link_front_left_wheel" />
        <parent link="link_left_hinge" />
        <origin xyz="0 0 0" rpy="0 0 0" />
        <axis xyz="0 1 0" />
    </joint>

    <!-- Joint - right hinge / front right wheel -->
    <joint name="joint_right_hinge_wheel" type="continuous">
        <child link="link_front_right_wheel" />
        <parent link="link_right_hinge" />
        <origin xyz="0 0 0" rpy="0 0 0" />
        <axis xyz="0 1 0" />
    </joint>

    <!-- Laser scan -->
    <joint name="joint_laser_scan_chassis" type="fixed">
        <origin rpy="0 0 0" xyz="0.8 0 0.4" />
        <child link="link_laser_scan" />
        <parent link="link_chassis" />
        <joint_properties damping="1.0" friction="1.0" />
    </joint>
    <link name="link_laser_scan">
        <inertial>
            <origin xyz="0 0 0" rpy="0 0 0" />
            <mass value="0.5" />
            <inertia ixx="0.000252666666667" ixy="0" ixz="0" iyy="0.000252666666667" iyz="0" izz="0.0005"/>
        </inertial>
        <visual>
            <origin xyz="0 0 0" rpy="0 0 0" />
            <geometry>
                <cylinder radius="0.15" length="0.40"/>
            </geometry>
            <material name="Red">
                <color rgba="0.7 0.1 0.1 1" />
            </material>
        </visual>
        <collision>
            <origin xyz="0 0 0" rpy="0 0 0"/>
            <geometry>
                <cylinder radius="0.15" length="0.40"/>
            </geometry>
        </collision>
    </link>

</robot>
